TESTS WITH ERRORS 
test03 (gradingtests.UnitTests)
Traceback (most recent call last):
  File "/Users/k2i/academics/automatedgradingapp/app/testing/kb-inference-ec/gradingtests.py", line 73, in test03
    self.compare(self.KB.kb_explain(fact4), answer1)
  File "/Users/k2i/academics/automatedgradingapp/app/testing/kb-inference-ec/student_code.py", line 151, in kb_explain
    s = self.get_state_string(facts)
  File "/Users/k2i/academics/automatedgradingapp/app/testing/kb-inference-ec/student_code.py", line 222, in get_state_string
    s = 'fact: (' + fr.statement.predicate + ' ' + fr.statement.terms[0].term.element + ' ' + fr.statement.terms[1].term.element + ')'
IndexError: list index out of range

-------------------------------
TESTS FAILED  
-------------------------------
TESTS SKIPPED 
-------------------------------
